2025-09-01 07:35:18,724 - main - ERROR - [VALIDATION_ERROR] Validation failed | CID: 95110f3e46624311987bfda698529e2a | Path: http://100.64.143.61:8000/render | Errors: [{'type': 'value_error', 'loc': ('body', 'text'), 'msg': 'Value error, テキストが空です', 'input': '', 'ctx': {'error': ValueError('テキストが空です')}}] | Body: {"text":"","font_size":20}
2025-09-01 07:35:18,724 - main - ERROR - [INTERNAL_ERROR] Unhandled exception | CID: b2b696464a474ed8b7b74f60dd8337a2 | Path: http://100.64.143.61:8000/render
Traceback (most recent call last):
  File "/usr/local/lib/python3.10/dist-packages/starlette/_exception_handler.py", line 42, in wrapped_app
    await app(scope, receive, sender)
  File "/usr/local/lib/python3.10/dist-packages/starlette/routing.py", line 75, in app
    response = await f(request)
  File "/usr/local/lib/python3.10/dist-packages/fastapi/routing.py", line 347, in app
    raise validation_error
fastapi.exceptions.RequestValidationError: [{'type': 'value_error', 'loc': ('body', 'text'), 'msg': 'Value error, テキストが空です', 'input': '', 'ctx': {'error': ValueError('テキストが空です')}}]

During handling of the above exception, another exception occurred:

Traceback (most recent call last):
  File "/usr/local/lib/python3.10/dist-packages/starlette/middleware/errors.py", line 164, in __call__
    await self.app(scope, receive, _send)
  File "/usr/local/lib/python3.10/dist-packages/starlette/middleware/exceptions.py", line 63, in __call__
    await wrap_app_handling_exceptions(self.app, conn)(scope, receive, send)
  File "/usr/local/lib/python3.10/dist-packages/starlette/_exception_handler.py", line 53, in wrapped_app
    raise exc
  File "/usr/local/lib/python3.10/dist-packages/starlette/_exception_handler.py", line 42, in wrapped_app
    await app(scope, receive, sender)
  File "/usr/local/lib/python3.10/dist-packages/starlette/routing.py", line 716, in __call__
    await self.middleware_stack(scope, receive, send)
  File "/usr/local/lib/python3.10/dist-packages/starlette/routing.py", line 736, in app
    await route.handle(scope, receive, send)
  File "/usr/local/lib/python3.10/dist-packages/starlette/routing.py", line 290, in handle
    await self.app(scope, receive, send)
  File "/usr/local/lib/python3.10/dist-packages/starlette/routing.py", line 78, in app
    await wrap_app_handling_exceptions(app, request)(scope, receive, send)
  File "/usr/local/lib/python3.10/dist-packages/starlette/_exception_handler.py", line 59, in wrapped_app
    response = await handler(conn, exc)
  File "/app/main.py", line 184, in validation_exception_handler
    return JSONResponse(
  File "/usr/local/lib/python3.10/dist-packages/starlette/responses.py", line 190, in __init__
    super().__init__(content, status_code, headers, media_type, background)
  File "/usr/local/lib/python3.10/dist-packages/starlette/responses.py", line 47, in __init__
    self.body = self.render(content)
  File "/usr/local/lib/python3.10/dist-packages/starlette/responses.py", line 193, in render
    return json.dumps(
  File "/usr/lib/python3.10/json/__init__.py", line 238, in dumps
    **kw).encode(obj)
  File "/usr/lib/python3.10/json/encoder.py", line 199, in encode
    chunks = self.iterencode(o, _one_shot=True)
  File "/usr/lib/python3.10/json/encoder.py", line 257, in iterencode
    return _iterencode(o, 0)
  File "/usr/lib/python3.10/json/encoder.py", line 179, in default
    raise TypeError(f'Object of type {o.__class__.__name__} '
TypeError: Object of type ValueError is not JSON serializable
2025-09-01 07:35:36,671 - main - ERROR - [UNAUTHORIZED] Unauthorized | CID: 30a902a718c3477093e5b4aa29a2a962 | Path: http://100.64.143.61:8000/render | Status: 401 | Detail: Unauthorized
2025-09-01 07:37:51,384 - main - ERROR - [NOT_FOUND] Not Found | CID: 1217f52bf6524e69a34d12d126abcdca | Path: http://localhost:8000/favicon.ico | Status: 404 | Detail: Not Found
2025-09-01 07:38:46,569 - main - ERROR - [VALIDATION_ERROR] Validation failed | CID: 02dba528563b45d599641ce7f6c5580a | Path: http://100.64.143.61:8000/render | Errors: [{'type': 'value_error', 'loc': ('body', 'text'), 'msg': 'Value error, テキストが空です', 'input': '', 'ctx': {'error': ValueError('テキストが空です')}}] | Body: {"text":"","font_size":20}
2025-09-01 07:38:46,570 - main - ERROR - [INTERNAL_ERROR] Unhandled exception | CID: a9de9936358c4a5eb96772ac69afb7e9 | Path: http://100.64.143.61:8000/render
Traceback (most recent call last):
  File "/usr/local/lib/python3.10/dist-packages/starlette/_exception_handler.py", line 42, in wrapped_app
    await app(scope, receive, sender)
  File "/usr/local/lib/python3.10/dist-packages/starlette/routing.py", line 75, in app
    response = await f(request)
  File "/usr/local/lib/python3.10/dist-packages/fastapi/routing.py", line 347, in app
    raise validation_error
fastapi.exceptions.RequestValidationError: [{'type': 'value_error', 'loc': ('body', 'text'), 'msg': 'Value error, テキストが空です', 'input': '', 'ctx': {'error': ValueError('テキストが空です')}}]

During handling of the above exception, another exception occurred:

Traceback (most recent call last):
  File "/usr/local/lib/python3.10/dist-packages/starlette/middleware/errors.py", line 164, in __call__
    await self.app(scope, receive, _send)
  File "/usr/local/lib/python3.10/dist-packages/starlette/middleware/exceptions.py", line 63, in __call__
    await wrap_app_handling_exceptions(self.app, conn)(scope, receive, send)
  File "/usr/local/lib/python3.10/dist-packages/starlette/_exception_handler.py", line 53, in wrapped_app
    raise exc
  File "/usr/local/lib/python3.10/dist-packages/starlette/_exception_handler.py", line 42, in wrapped_app
    await app(scope, receive, sender)
  File "/usr/local/lib/python3.10/dist-packages/starlette/routing.py", line 716, in __call__
    await self.middleware_stack(scope, receive, send)
  File "/usr/local/lib/python3.10/dist-packages/starlette/routing.py", line 736, in app
    await route.handle(scope, receive, send)
  File "/usr/local/lib/python3.10/dist-packages/starlette/routing.py", line 290, in handle
    await self.app(scope, receive, send)
  File "/usr/local/lib/python3.10/dist-packages/starlette/routing.py", line 78, in app
    await wrap_app_handling_exceptions(app, request)(scope, receive, send)
  File "/usr/local/lib/python3.10/dist-packages/starlette/_exception_handler.py", line 59, in wrapped_app
    response = await handler(conn, exc)
  File "/app/main.py", line 184, in validation_exception_handler
    return JSONResponse(
  File "/usr/local/lib/python3.10/dist-packages/starlette/responses.py", line 190, in __init__
    super().__init__(content, status_code, headers, media_type, background)
  File "/usr/local/lib/python3.10/dist-packages/starlette/responses.py", line 47, in __init__
    self.body = self.render(content)
  File "/usr/local/lib/python3.10/dist-packages/starlette/responses.py", line 193, in render
    return json.dumps(
  File "/usr/lib/python3.10/json/__init__.py", line 238, in dumps
    **kw).encode(obj)
  File "/usr/lib/python3.10/json/encoder.py", line 199, in encode
    chunks = self.iterencode(o, _one_shot=True)
  File "/usr/lib/python3.10/json/encoder.py", line 257, in iterencode
    return _iterencode(o, 0)
  File "/usr/lib/python3.10/json/encoder.py", line 179, in default
    raise TypeError(f'Object of type {o.__class__.__name__} '
TypeError: Object of type ValueError is not JSON serializable
2025-09-01 07:40:33,102 - main - ERROR - [VALIDATION_ERROR] Validation failed | CID: 8355d85cf8c6431cae0bd4381e775500 | Path: http://100.64.143.61:8000/render | Errors: [{'type': 'value_error', 'loc': ('body', 'text'), 'msg': 'Value error, テキストが空です', 'input': '', 'ctx': {'error': ValueError('テキストが空です')}}] | Body: {"text":"","font_size":20}
2025-09-01 07:40:43,887 - main - ERROR - [UNAUTHORIZED] Unauthorized | CID: 45599eae29e24b37bb04f21bf13b8665 | Path: http://100.64.143.61:8000/render | Status: 401 | Detail: Unauthorized
